Traceback (most recent call last):
  File "/home/geez219/anaconda3/envs/tf2.1/bin/papermill", line 5, in <module>
    from papermill.cli import papermill
  File "/home/geez219/anaconda3/envs/tf2.1/lib/python3.6/site-packages/papermill/__init__.py", line 4, in <module>
    from .execute import execute_notebook
  File "/home/geez219/anaconda3/envs/tf2.1/lib/python3.6/site-packages/papermill/execute.py", line 8, in <module>
    from .iorw import load_notebook_node, write_ipynb, get_pretty_path, local_file_io_cwd
  File "/home/geez219/anaconda3/envs/tf2.1/lib/python3.6/site-packages/papermill/iorw.py", line 29, in <module>
    from .s3 import S3
  File "/home/geez219/anaconda3/envs/tf2.1/lib/python3.6/site-packages/papermill/s3.py", line 10, in <module>
    from boto3.session import Session
  File "/home/geez219/anaconda3/envs/tf2.1/lib/python3.6/site-packages/boto3/__init__.py", line 16, in <module>
    from boto3.session import Session
  File "/home/geez219/anaconda3/envs/tf2.1/lib/python3.6/site-packages/boto3/session.py", line 17, in <module>
    import botocore.session
  File "/home/geez219/anaconda3/envs/tf2.1/lib/python3.6/site-packages/botocore/session.py", line 28, in <module>
    import botocore.configloader
  File "/home/geez219/anaconda3/envs/tf2.1/lib/python3.6/site-packages/botocore/configloader.py", line 19, in <module>
    from botocore.compat import six
  File "/home/geez219/anaconda3/envs/tf2.1/lib/python3.6/site-packages/botocore/compat.py", line 25, in <module>
    from botocore.exceptions import MD5UnavailableError
  File "/home/geez219/anaconda3/envs/tf2.1/lib/python3.6/site-packages/botocore/exceptions.py", line 15, in <module>
    from botocore.vendored import requests
  File "/home/geez219/anaconda3/envs/tf2.1/lib/python3.6/site-packages/botocore/vendored/requests/__init__.py", line 7, in <module>
    from .exceptions import (
  File "/home/geez219/anaconda3/envs/tf2.1/lib/python3.6/site-packages/botocore/vendored/requests/exceptions.py", line 10, in <module>
    from .packages.urllib3.exceptions import HTTPError as BaseHTTPError
  File "/home/geez219/anaconda3/envs/tf2.1/lib/python3.6/site-packages/botocore/vendored/requests/packages/__init__.py", line 3, in <module>
    from . import urllib3
  File "/home/geez219/anaconda3/envs/tf2.1/lib/python3.6/site-packages/botocore/vendored/requests/packages/urllib3/__init__.py", line 6, in <module>
    __license__ = 'MIT'
KeyboardInterrupt
